<?xml version="1.0" ?>
<!-- =================================================================================== -->
<!-- |    This document was autogenerated by xacro from spot.urdf.xacro                | -->
<!-- |    EDITING THIS FILE BY HAND IS NOT RECOMMENDED                                 | -->
<!-- =================================================================================== -->
<robot name="spot">
  <mujoco>
    <compiler discardvisual="false"/>
  </mujoco>
  <!-- Body -->
  <link name="body">
    <visual>
      <geometry>
        <mesh filename="body.obj"/>
      </geometry>
    </visual>
    <collision>
      <geometry>
        <mesh filename="body_collision.stl"/>
      </geometry>
    </collision>
    <inertial>
      <mass value="16.25"/>
      <inertia ixx="0.085" ixy="0.0" ixz="0.0" iyy="1.045" iyz="0.0" izz="1.042"/>
    </inertial>
  </link>
  <!-- Base link -->
  <link name="base_link"/>
  <joint name="base_link_joint" type="fixed">
    <origin rpy="0 0 0" xyz="0 0 0"/>
    <parent link="body"/>
    <child link="base_link"/>
  </joint>
  <!-- Front rail -->
  <link name="front_rail"/>
  <joint name="front_rail_joint" type="fixed">
    <origin rpy="0 0 0" xyz="0.223 0 0.04505"/>
    <parent link="body"/>
    <child link="front_rail"/>
  </joint>
  <!-- Rear rail -->
  <link name="rear_rail"/>
  <joint name="rear_rail_joint" type="fixed">
    <origin rpy="0 0 0" xyz="-0.223 0 0.04505"/>
    <parent link="body"/>
    <child link="rear_rail"/>
  </joint>
  <!-- front_left_hip -->
  <link name="front_left_hip">
    <visual>
      <geometry>
        <mesh filename="front_left_hip.obj"/>
      </geometry>
    </visual>
    <collision>
      <geometry>
        <mesh filename="front_left_hip_collision.stl"/>
      </geometry>
    </collision>
    <inertial>
      <mass value="1.5"/>
      <inertia ixx="0.0605" ixy="0.0" ixz="0.0" iyy="0.0605" iyz="0.0" izz="0.0605"/>
    </inertial>
  </link>
  <joint name="front_left_hip_x" type="revolute">
    <origin rpy="0 0 0" xyz="0.29785 0.05500 0.00000"/>
    <axis xyz="1 0 0"/>
    <parent link="body"/>
    <child link="front_left_hip"/>
    <dynamics damping="0.1" friction="0.1"/>
    <limit effort="1000" lower="-0.78539816339744827899" upper="0.78539816339744827899" velocity="1000.00"/>
  </joint>
  <transmission name="front_left_hip_x_trans">
    <type>transmission_interface/SimpleTransmission</type>
    <joint name="front_left_hip_x">
      <hardwareInterface>EffortJointInterface</hardwareInterface>
    </joint>
    <actuator name="front_left_hip_x">
      <mechanicalReduction>50</mechanicalReduction>
      <hardwareInterface>EffortJointInterface</hardwareInterface>
    </actuator>
  </transmission>
  <!-- front_left_upper_leg -->
  <link name="front_left_upper_leg">
    <visual>
      <geometry>
        <mesh filename="front_left_upper_leg.obj"/>
      </geometry>
    </visual>
    <collision>
      <geometry>
        <mesh filename="front_left_upper_leg_collision.stl"/>
      </geometry>
    </collision>
    <inertial>
      <mass value="1.5"/>
      <inertia ixx="0.05" ixy="0.0" ixz="0.0" iyy="0.05" iyz="0.0" izz="0.05"/>
    </inertial>
  </link>
  <joint name="front_left_hip_y" type="revolute">
    <origin rpy="0 0 0" xyz="0.0 0.110945 0.0"/>
    <axis xyz="0 1 0"/>
    <parent link="front_left_hip"/>
    <child link="front_left_upper_leg"/>
    <dynamics damping="0.1" friction="0.1"/>
    <limit effort="1000" lower="-0.89884456477707963539" upper="2.2951079663725435509" velocity="1000.00"/>
  </joint>
  <transmission name="front_left_hip_y_trans">
    <type>transmission_interface/SimpleTransmission</type>
    <joint name="front_left_hip_y">
      <hardwareInterface>EffortJointInterface</hardwareInterface>
    </joint>
    <actuator name="front_left_hip_y">
      <mechanicalReduction>50</mechanicalReduction>
      <hardwareInterface>EffortJointInterface</hardwareInterface>
    </actuator>
  </transmission>
  <!-- Additional links and joints have been similarly adjusted for inertia values -->
</robot>

